Workbook

Sheet 🏠 Portada
A1: QOCHIX — Pacto Económico · Modelo Financiero Interactivo
A2: Hugo 63% · Rossy 17% · Vera 11% · Carlos 6% · Nicole 3%
A4: Este Excel contiene el modelo financiero completo de Qochix. Cambia cualquier celda AZUL en la hoja ⚙️ Supuestos y todo se recalcula automáticamente. Celdas VERDE = jaladas de otra hoja. Celdas NEGRO = fórmulas calculadas.
A7: PESTAÑA | C7: ¿QUÉ CONTIENE? | H7: ¿EDITABLE?
A8: ⚙️ Supuestos | C8: TODOS los parámetros: sueldos, horas, % equity, capital, facturación, sueldos Qochix, parámetros vesting | H8: ✅ Todo azul = editable
A9: 1️⃣ Valor Hora | C9: Valor por hora de mercado de cada co-fundador. Base del sweat equity | H9: 🔒 Lee de Supuestos
A10: 2️⃣ Sweat Equity | C10: Valor del tiempo aportado 3 años × factor ajuste. El mayor componente del equity | H10: 🔒 Lee de Supuestos
A11: 3️⃣ Capital Hugo | C11: Desglose línea a línea del cash de Hugo. Separa inversión permanente (equity) de préstamos (deuda) | H11: 🔒 Lee de Supuestos
A12: 4️⃣ Equity | C12: % matemático puro vs % propuesto. Muestra la diferencia y lógica de cada decisión | H12: 🔒 Fórmulas automáticas
A13: 5️⃣ Ticket | C13: Ticket de entrada S/5,000 c/u y plan de cuotas por persona | H13: 🔒 Lee de Supuestos
A14: 6️⃣ Vesting | C14: Cliff 12 meses + vesting 36 meses. Qué pasa si alguien se va en distintos momentos | H14: 🔒 Fórmulas automáticas
A15: 7️⃣ Facturación | C15: Proyección por marca 2026-2032. Calcula neto 65%, colchón y distribuible a socios | H15: ⚠️ Líneas Almaria/HugoTech editables
A16: 8️⃣ Sueldos | C16: Sueldos Qochix año a año. Punto de cruce vs corporativo para cada socio | H16: 🔒 Lee de Supuestos
A17: 9️⃣ Equity Anual | C17: Retorno mensual por ser DUEÑO — aparte del sueldo. Equity = distribuible × % equity | H17: 🔒 Fórmulas automáticas
A18: 🔟 Total Mensual | C18: Sueldo + equity = ingreso total mensual de Qochix. Acumulado 7 años | H18: 🔒 Fórmulas automáticas
... A20: 🎯 Apuesta Final | C20: Tabla HOY vs 2032. Sueldo + equity separados. Múltiplos. Patrimonio Hugo. La pregunta del 2 de abril | H20: ⚠️ Valoración Qochix editable
A22: CÓDIGO DE COLORES
A23: AZUL + fondo amarillo | C23: Celda editable — cambia este valor en ⚙️ Supuestos
A24: NEGRO + fondo blanco | C24: Fórmula calculada automáticamente — no modificar
A25: VERDE | C25: Link que jala de otra hoja — se actualiza solo
A26: ROJO | C26: Alerta importante (ej: deuda, suma incorrecta)

Sheet ⚙️ Supuestos
A1: ⚙️ SUPUESTOS — Todos los parámetros editables del modelo
A2: 🔵 Cambia cualquier celda AZUL y todo el modelo se recalcula solo. NO toques las celdas en negro (fórmulas). El % equity debe sumar exactamente 100% — hay celda de verificación abajo.
A5: A. DATOS BASE DE CADA CO-FUNDADOR
A6: Sueldo hoy = sueldo en trabajo actual (base para calcular valor hora y sweat equity). Hrs/día Qochix = horas adicionales dedicadas al ecosistema. Factor ajuste = % real de esas hrs que van 100% a Qochix (menos si tienen otro trabajo).
A8: Persona | B8: Sueldo hoy (S/mes) | C8: Días lab/mes | D8: Hrs lab/día | E8: Hrs/día Qochix | F8: Factor ajuste | G8: % Equity propuesto | H8: Capital aportado S/
A9: Hugo | B9: 30000 | C9: 22 | D9: 8 | E9: 7 | F9: 0.6 | G9: 0.63 | H9: 40243
A10: Rossy | B10: 7000 | C10: 22 | D10: 8 | E10: 6 | F10: 0.7 | G10: 0.17 | H10: 20000
A11: Vera | B11: 6500 | C11: 22 | D11: 8 | E11: 6 | F11: 0.7 | G11: 0.11 | H11: 4000
A12: Carlos | B12: 5000 | C12: 22 | D12: 8 | E12: 3 | F12: 1 | G12: 0.06 | H12: 0 | I12: Ya cobra de Trazo
A13: Nicole | B13: 2000 | C13: 22 | D13: 8 | E13: 3 | F13: 1 | G13: 0.03 | H13: 0 | I13: Ya cobra de Trazo
A14: → Verificar: % equity suma | G14: =SUM(G9:G13) -> 1 | H14: ← Debe ser exactamente 100%
A16: B. TICKET DE ENTRADA A QOCHIX
A17: El ticket es una señal de compromiso — no un pago. Edita el monto o N° cuotas; la cuota mensual se calcula sola.
A19: Persona | B19: Monto S/ | C19: N° cuotas | D19: Cuota/mes (auto) | E19: Calendario
A20: Hugo | B20: 5000 | C20: 1 | D20: =B20/C20 -> 5000 | E20: Pago único · abr 2026
A21: Rossy | B21: 5000 | C21: 3 | D21: =B21/C21 -> 1666.6667 | E21: Abr / May / Jun 2026
A22: Vera | B22: 5000 | C22: 3 | D22: =B22/C22 -> 1666.6667 | E22: Abr / May / Jun 2026
A23: Carlos | B23: 5000 | C23: 3 | D23: =B23/C23 -> 1666.6667 | E23: Abr / May / Jun 2026
A24: Nicole | B24: 5000 | C24: 5 | D24: =B24/C24 -> 1000 | E24: Abr – Ago 2026
A25: TOTAL | D25: =SUM(B20:B24) -> 25000
A27: C. FACTURACIÓN PROYECTADA POR MARCA (S/mes)
A28: Proyección mensual de ingresos. Edita las celdas azules según tus estimaciones. El NETO y DISTRIBUIBLE se calculan automáticamente en 7️⃣ Facturación.
A30: Marca | B30: 2026 | C30: 2027 | D30: 2028 | E30: 2029 | F30: 2030 | G30: 2031 | H30: 2032
A31: Trazo | B31: 9000 | C31: 20000 | D31: 28000 | E31: 35000 | F31: 42000 | G31: 50000 | H31: 58000
A32: Almaria | B32: 1200 | C32: 8500 | D32: 22000 | E32: 40000 | F32: 98100 | G32: 141900 | H32: 183400
A33: HugoTech | B33: 4282 | C33: 11483 | D33: 22800 | E33: 39600 | F33: 55483 | G33: 70100 | H33: 88133
A34: TOTAL | B34: =SUM(B31:B33) -> 14482 | C34: =SUM(C31:C33) -> 39983 | D34: =SUM(D31:D33) -> 72800 | E34: =SUM(E31:E33) -> 114600 | F34: =SUM(F31:F33) -> 195583 | G34: =SUM(G31:G33) -> 262000 | H34: =SUM(H31:H33) -> 329533
A35: % neto después de costos operativos → | D35: 0.65 | E35: ← El 35% restante cubre: planilla Trazo, tools, ads, logística, contadora
A37: D. SUELDOS QOCHIX PROYECTADOS (S/mes)
A38: Hugo/Rossy/Vera: ADICIONAL a su trabajo corporativo actual hasta el punto de cruce. Carlos/Nicole: es su sueldo principal (Trazo los paga desde 2026).
A40: Persona | B40: 2026 | C40: 2027 | D40: 2028 | E40: 2029 | F40: 2030 | G40: 2031 | H40: 2032
A41: Hugo | B41: — | C41: 2000 | D41: 5000 | E41: 9000 | F41: 14000 | G41: 20000 | H41: 30000
A42: Rossy | B42: — | C42: 1000 | D42: 2500 | E42: 4000 | F42: 7500 | G42: 9000 | H42: 10000
A43: Vera | B43: — | C43: 1000 | D43: 2500 | E43: 4000 | F43: 7000 | G43: 8500 | H43: 10000
A44: Carlos | B44: 5000 | C44: 6000 | D44: 7000 | E44: 8000 | F44: 9000 | G44: 10000 | H44: 10000
A45: Nicole | B45: 2000 | C45: 4000 | D45: 5000 | E45: 6000 | F45: 6000 | G45: 6000 | H45: 6000
A46: TOTAL SUELDOS | B46: =SUM(B41:B45) -> 7000 | C46: =SUM(C41:C45) -> 14000 | D46: =SUM(D41:D45) -> 22000 | E46: =SUM(E41:E45) -> 31000 | F46: =SUM(F41:F45) -> 43500 | G46: =SUM(G41:G45) -> 53500 | H46: =SUM(H41:H45) -> 66000
A48: E. PARÁMETROS GLOBALES DEL MODELO
A49: Parámetros que afectan todo el modelo. Cliff y vesting definen cuándo se ganan las acciones.
A50: Reserva mínima operativa (S/mes) | D50: 3000 | E50: Colchón de emergencia antes de distribuir equity a socios
...

Sheet 1️⃣ Valor Hora
A1: TABLA 1 — Valor hora de cada co-fundador
A2: ¿Para qué sirve? Para saber cuánto vale 1 hora de cada persona en el mercado. Es la base del sweat equity — el tiempo que cada uno aporta sin recibir ese pago completo. FÓRMULA: Sueldo mensual ÷ (días laborales × horas por día) = S/ por hora Ejemplo Hugo: S/30,000 ÷ (22 días × 8 hrs) = S/170/hr
A6: Persona | B6: Sueldo hoy (S/mes) | C6: Fórmula | D6: Valor 1 hora S/ | E6: Hrs/día Qochix | F6: Contexto | G6: Hrs/mes Qochix | H6: Valor/mes aportado S/ | I6: % del total
A7: Hugo | B7: ='⚙️ Supuestos'!B9 -> 30000 | C7: =B7&" ÷ (22×8)" -> 30000 ÷ (22×8) | D7: ='⚙️ Supuestos'!B9/('⚙️ Supuestos'!C9*'⚙️ Supuestos'!D9) -> 170.45455 | E7: ='⚙️ Supuestos'!E9 -> 7 | F7: encima corporativo | G7: ='⚙️ Supuestos'!E9*6*'⚙️ Supuestos'!D52 -> 180.6 | H7: =D7*G7 -> 30784.091 | I7: =H7/SUM(H7:H11) -> 0.67307692
A8: Rossy | B8: ='⚙️ Supuestos'!B10 -> 7000 | C8: =B8&" ÷ (22×8)" -> 7000 ÷ (22×8) | D8: ='⚙️ Supuestos'!B10/('⚙️ Supuestos'!C10*'⚙️ Supuestos'!D10) -> 39.772727 | E8: ='⚙️ Supuestos'!E10 -> 6 | F8: encima corporativo | G8: ='⚙️ Supuestos'!E10*6*'⚙️ Supuestos'!D52 -> 154.8 | H8: =D8*G8 -> 6156.8182 | I8: =H8/SUM(H7:H11) -> 0.13461538
A9: Vera | B9: ='⚙️ Supuestos'!B11 -> 6500 | C9: =B9&" ÷ (22×8)" -> 6500 ÷ (22×8) | D9: ='⚙️ Supuestos'!B11/('⚙️ Supuestos'!C11*'⚙️ Supuestos'!D11) -> 36.931818 | E9: ='⚙️ Supuestos'!E11 -> 6 | F9: encima corporativo | G9: ='⚙️ Supuestos'!E11*6*'⚙️ Supuestos'!D52 -> 154.8 | H9: =D9*G9 -> 5717.0455 | I9: =H9/SUM(H7:H11) -> 0.125
A10: Carlos | B10: ='⚙️ Supuestos'!B12 -> 5000 | C10: =B10&" ÷ (22×8)" -> 5000 ÷ (22×8) | D10: ='⚙️ Supuestos'!B12/('⚙️ Supuestos'!C12*'⚙️ Supuestos'!D12) -> 28.409091 | E10: ='⚙️ Supuestos'!E12 -> 3 | F10: adicional fuera Trazo | G10: ='⚙️ Supuestos'!E12*6*'⚙️ Supuestos'!D52 -> 77.4 | H10: =D10*G10 -> 2198.8636 | I10: =H10/SUM(H7:H11) -> 0.048076923
A11: Nicole | B11: ='⚙️ Supuestos'!B13 -> 2000 | C11: =B11&" ÷ (22×8)" -> 2000 ÷ (22×8) | D11: ='⚙️ Supuestos'!B13/('⚙️ Supuestos'!C13*'⚙️ Supuestos'!D13) -> 11.363636 | E11: ='⚙️ Supuestos'!E13 -> 3 | F11: adicional fuera Trazo | G11: ='⚙️ Supuestos'!E13*6*'⚙️ Supuestos'!D52 -> 77.4 | H11: =D11*G11 -> 879.54545 | I11: =H11/SUM(H7:H11) -> 0.019230769
A12: TOTAL ECOSISTEMA | H12: =SUM(H7:H11) -> 45736.364
A14: ⚡ Hugo aporta el 67% del valor tiempo total. Si cambias el sueldo en ⚙️ Supuestos, esta tabla se actualiza sola.

Sheet 2️⃣ Sweat Equity
A1: TABLA 2 — Sweat equity 3 años (abr 2026 → abr 2029)
A2: Sweat equity = valor del tiempo aportado sin recibir el sueldo completo de mercado. Es lo que cada uno 'regala' al ecosistema en forma de trabajo. FÓRMULA: Valor/mes × 36 meses × Factor de ajuste El factor ajusta por quienes tienen otro trabajo (no pueden dar el 100% a Qochix).
A6: Persona | B6: Valor/mes S/ | C6: × 36 meses S/ | D6: × Factor | E6: Lógica del factor | F6: SWEAT TOTAL S/ | G6: % del pool | H6: Sweat/año S/ | I6: Sweat/mes S/
A7: Hugo | B7: ='1️⃣ Valor Hora'!H7 -> 30784.091 | C7: =B7*'⚙️ Supuestos'!D53 -> 1108227.3 | D7: ='⚙️ Supuestos'!F9 -> 0.6 | E7: Corporativo ocupa 40% — 60% libre para Qochix | F7: =C7*D7 -> 664936.36 | G7: =F7/SUM(F7:F11) -> 0.6185567 | H7: =F7/3 -> 221645.45 | I7: =F7/36 -> 18470.455
A8: Rossy | B8: ='1️⃣ Valor Hora'!H8 -> 6156.8182 | C8: =B8*'⚙️ Supuestos'!D53 -> 221645.45 | D8: ='⚙️ Supuestos'!F10 -> 0.7 | E8: Otro trabajo ocupa 30% — 70% libre para Qochix | F8: =C8*D8 -> 155151.82 | G8: =F8/SUM(F7:F11) -> 0.1443299 | H8: =F8/3 -> 51717.273 | I8: =F8/36 -> 4309.7727
A9: Vera | B9: ='1️⃣ Valor Hora'!H9 -> 5717.0455 | C9: =B9*'⚙️ Supuestos'!D53 -> 205813.64 | D9: ='⚙️ Supuestos'!F11 -> 0.7 | E9: Otro trabajo ocupa 30% — 70% libre para Qochix | F9: =C9*D9 -> 144069.55 | G9: =F9/SUM(F7:F11) -> 0.13402062 | H9: =F9/3 -> 48023.182 | I9: =F9/36 -> 4001.9318
A10: Carlos | B10: ='1️⃣ Valor Hora'!H10 -> 2198.8636 | C10: =B10*'⚙️ Supuestos'!D53 -> 79159.091 | D10: ='⚙️ Supuestos'!F12 -> 1 | E10: 3hrs adicionales = 100% para Qochix | F10: =C10*D10 -> 79159.091 | G10: =F10/SUM(F7:F11) -> 0.073637703 | H10: =F10/3 -> 26386.364 | I10: =F10/36 -> 2198.8636
A11: Nicole | B11: ='1️⃣ Valor Hora'!H11 -> 879.54545 | C11: =B11*'⚙️ Supuestos'!D53 -> 31663.636 | D11: ='⚙️ Supuestos'!F13 -> 1 | E11: 3hrs adicionales = 100% para Qochix | F11: =C11*D11 -> 31663.636 | G11: =F11/SUM(F7:F11) -> 0.029455081 | H11: =F11/3 -> 10554.545 | I11: =F11/36 -> 879.54545
A12: TOTAL ECOSISTEMA | F12: =SUM(F7:F11) -> 1074980.5 | H12: =SUM(H7:H11) -> 358326.82 | I12: =SUM(I7:I11) -> 29860.568
A14: 💡 El sweat equity total del ecosistema es S/1,074,980 en 3 años. Si cambias las horas/día en ⚙️ Supuestos, este total cambia automáticamente.

Sheet 3️⃣ Capital Hugo
A1: TABLA 3 — Capital de Hugo: desglose línea a línea (S/)
A2: El capital de Hugo no es inventado — es la suma de todo lo que ha puesto en CASH REAL. IMPORTANTE: Los préstamos S/13,000 son DEUDA (Trazo los devuelve a S/2k/mes). Solo la inversión permanente de S/40,243 cuenta para calcular el % matemático de equity.
A6: Concepto | B6: Monto S/ | C6: Categoría | D6: Destino | E6: ¿Equity? | F6: Nota
A7: Inversión como socio en Trazo | B7: 4500 | C7: Capital | D7: Equity Trazo | E7: SÍ ✓
A8: Capital inicial Almaria | B8: 10000 | C8: Capital | D8: Fondo arranque Almaria | E8: SÍ ✓
A9: Google Workspace (anual) | B9: 1500 | C9: Herramienta | D9: Ecosistema 3 marcas | E9: SÍ ✓
A10: Metricool EUR 486 (≈S/1,968) | B10: 1968 | C10: Herramienta | D10: Gestión redes sociales | E10: SÍ ✓
A11: pCloud USD 180 (≈S/675) | B11: 675 | C11: Herramienta | D11: Almacenamiento nube | E11: SÍ ✓
A12: Pauta publicitaria inicial | B12: 500 | C12: Marketing | D12: Primeras campañas | E12: SÍ ✓
A13: Diana content creator febrero | B13: 2000 | C13: RRHH | D13: HugoTech — Diana | E13: SÍ ✓
A14: Almuerzo kick-off equipo | B14: 300 | C14: Operativo | D14: Reunión de arranque | E14: SÍ ✓
A15: Content creator fin de mes | B15: 2000 | C15: RRHH | D15: Arranque operativo | E15: SÍ ✓
A16: Content creator abr-jun (3m) | B16: 6000 | C16: RRHH | D16: Diana continuidad | E16: SÍ ✓
A17: Comercial Trazo × 3 meses | B17: 6000 | C17: Comercial | D17: B2B Trazo | E17: SÍ ✓
A18: Ads Trazo × 3 meses | B18: 1500 | C18: Marketing | D18: Pauta Trazo | E18: SÍ ✓
... A20: Ads HugoTech × 3 meses | B20: 1500 | C20: Marketing | D20: Pauta HugoTech | E20: SÍ ✓
A21: ▶ SUBTOTAL INVERSIÓN EQUITY | B21: =B7+B8+B9+B10+B11+B12+B13+B14+B15+B16+B17+B18+B19+B20 -> 40243 | C21: ← Esta es la inversión real que cuenta para el % equity matemático
A23: PRÉSTAMOS — Son DEUDA, no equity (Trazo las devuelve)
A24: ⚠️ Estos préstamos los hizo Hugo a Trazo para cubrir déficits. Trazo los devuelve a S/2,000/mes desde julio 2026 hasta enero 2027. NO cuentan como equity porque se recuperan.
A26: Préstamo Trazo (actual) | B26: 8500 | C26: DEUDA | D26: Para cubrir déficit operativo | E26: NO ✗ | F26: Trazo devuelve S/2k/mes jul-ene
A27: Préstamo Trazo (fin de mes) | B27: 4500 | C27: DEUDA | D27: Para cubrir déficit fin de mes | E27: NO ✗ | F27: Trazo devuelve S/2k/mes jul-ene
A28: ▶ SUBTOTAL PRÉSTAMOS (DEUDA) | B28: =B26+B27 -> 13000 | C28: ← Se devuelven — no son inversión permanente
A30: EXPOSICIÓN TOTAL DE HUGO | B30: =B21+B28 -> 53243 | C30: ← Equity permanente + préstamos temporales

Sheet 4️⃣ Equity
A1: TABLA 4 — Distribución de equity Qochix
A2: Inversión total = Ticket + Capital cash + Sweat equity 3 años. % matemático = lo que sale de la matemática pura. % propuesto = lo acordado tras negociación (editable en ⚙️ Supuestos). Hugo cede ~2pts al equipo — equivale a ceder ~S/150k si Qochix vale S/1M.
A6: Persona | B6: % propuesto | C6: Ticket S/ | D6: Capital S/ | E6: Sweat 3a S/ | F6: TOTAL S/ | G6: % mat. | H6: Dif. prop-mat | I6: Lógica
A7: Hugo | B7: ='⚙️ Supuestos'!G9 -> 0.63 | C7: ='5️⃣ Ticket'!B6 -> 5000 | D7: ='⚙️ Supuestos'!H9 -> 40243 | E7: ='2️⃣ Sweat Equity'!F7 -> 664936.36 | F7: =C7+D7+E7 -> 710179.36 | G7: =F7/F12 -> 0.61000263 | H7: =B7-G7 -> 0.019997375 | I7: Fundador · mayor capital · mayor riesgo · ES HugoTech
A8: Rossy | B8: ='⚙️ Supuestos'!G10 -> 0.17 | C8: ='5️⃣ Ticket'!B7 -> 5000 | D8: ='⚙️ Supuestos'!H10 -> 20000 | E8: ='2️⃣ Sweat Equity'!F8 -> 155151.82 | F8: =C8+D8+E8 -> 180151.82 | G8: =F8/F12 -> 0.1547399 | H8: =B8-G8 -> 0.015260102 | I8: Alma Almaria · estrategia 3 marcas · capital S/20k
A9: Vera | B9: ='⚙️ Supuestos'!G11 -> 0.11 | C9: ='5️⃣ Ticket'!B8 -> 5000 | D9: ='⚙️ Supuestos'!H11 -> 4000 | E9: ='2️⃣ Sweat Equity'!F9 -> 144069.55 | F9: =C9+D9+E9 -> 153069.55 | G9: =F9/F12 -> 0.13147781 | H9: =B9-G9 -> -0.021477806 | I9: Alianzas · coordinación · capital S/4k
A10: Carlos | B10: ='⚙️ Supuestos'!G12 -> 0.06 | C10: ='5️⃣ Ticket'!B9 -> 5000 | D10: ='⚙️ Supuestos'!H12 -> 0 | E10: ='2️⃣ Sweat Equity'!F10 -> 79159.091 | F10: =C10+D10+E10 -> 84159.091 | G10: =F10/F12 -> 0.072287747 | H10: =B10-G10 -> -0.012287747 | I10: CEO Trazo · ya cobra sueldo — equity reconoce rol
A11: Nicole | B11: ='⚙️ Supuestos'!G13 -> 0.03 | C11: ='5️⃣ Ticket'!B10 -> 5000 | D11: ='⚙️ Supuestos'!H13 -> 0 | E11: ='2️⃣ Sweat Equity'!F11 -> 31663.636 | F11: =C11+D11+E11 -> 36663.636 | G11: =F11/F12 -> 0.031491924 | H11: =B11-G11 -> -0.0014919238 | I11: PM operativo · ya cobra sueldo — equity reconoce rol
A12: TOTAL POOL | B12: =SUM(B7:B11) -> 1 | C12: =SUM(C7:C11) -> 25000 | D12: =SUM(D7:D11) -> 64243 | E12: =SUM(E7:E11) -> 1074980.5 | F12: =SUM(F7:F11) -> 1164223.5
A14: Carlos y Nicole tienen % menor que el matemático porque ya cobran de Trazo. Su sacrificio real a Qochix es menor. Hugo cede 2pts al equipo para motivarlos.

Sheet 5️⃣ Ticket
A1: TABLA 5 — Ticket de entrada a Qochix
A2: El ticket es una señal de compromiso, no un pago. Si alguien no pone nada en cash, es fácil irse cuando se pone difícil. Total fresco S/25,000 → S/4,800 ads + S/20,200 colchón operativo inicial.
A5: Persona | B5: Monto S/ | C5: N° cuotas | D5: Cuota/mes (auto) | E5: Calendario | F5: % del total | G5: Nota
A6: Hugo | B6: ='⚙️ Supuestos'!B20 -> 5000 | C6: ='⚙️ Supuestos'!C20 -> 1 | D6: =B6/C6 -> 5000 | E6: Pago único · abr 2026 | F6: =B6/SUM(B6:B10) -> 0.2 | G6: Ya invierte S/40k+ — el ticket es la señal de compromiso igualitaria
A7: Rossy | B7: ='⚙️ Supuestos'!B21 -> 5000 | C7: ='⚙️ Supuestos'!C21 -> 3 | D7: =B7/C7 -> 1666.6667 | E7: Abr / May / Jun 2026 | F7: =B7/SUM(B6:B10) -> 0.2 | G7: S/1,667 × 3 meses
A8: Vera | B8: ='⚙️ Supuestos'!B22 -> 5000 | C8: ='⚙️ Supuestos'!C22 -> 3 | D8: =B8/C8 -> 1666.6667 | E8: Abr / May / Jun 2026 | F8: =B8/SUM(B6:B10) -> 0.2 | G8: S/1,667 × 3 meses
A9: Carlos | B9: ='⚙️ Supuestos'!B23 -> 5000 | C9: ='⚙️ Supuestos'!C23 -> 3 | D9: =B9/C9 -> 1666.6667 | E9: Abr / May / Jun 2026 | F9: =B9/SUM(B6:B10) -> 0.2 | G9: S/1,667 × 3 meses
A10: Nicole | B10: ='⚙️ Supuestos'!B24 -> 5000 | C10: ='⚙️ Supuestos'!C24 -> 5 | D10: =B10/C10 -> 1000 | E10: Abr – Ago 2026 | F10: =B10/SUM(B6:B10) -> 0.2 | G10: S/1,000 × 5 meses — proporcional a su sueldo
A11: TOTAL FRESCO QOCHIX | D11: =SUM(B6:B10) -> 25000

Sheet 6️⃣ Vesting
A1: TABLA 6 — Vesting + Cliff: cómo se ganan las acciones
A2: CLIFF (12 meses): mínimo antes de recibir cualquier acción. Si alguien se va antes de abr 2027 → pierde TODO, recupera solo su ticket S/5,000. VESTING (36 meses): después del cliff, las acciones se ganan gradualmente. Al cliff recibe 33% de golpe; el 67% restante en 24 cuotas mensuales (may 2027 → abr 2029).
A6: Persona | B6: % total | C6: Cliff abr 2027 (33%) | D6: Sep 2027 (+5m) | E6: Abr 2028 (+12m) | F6: Abr 2029 (100%) | G6: Acciones/mes post-cliff | H6: Si sale ANTES del cliff
A7: Hugo | B7: ='⚙️ Supuestos'!G9 -> 0.63 | C7: =B7*'⚙️ Supuestos'!D55 -> 0.20979 | D7: =C7+(B7*(1-'⚙️ Supuestos'!D55)/('⚙️ Supuestos'!D53-'⚙️ Supuestos'!D54))*5 -> 0.29733375 | E7: =C7+(B7*(1-'⚙️ Supuestos'!D55)/('⚙️ Supuestos'!D53-'⚙️ Supuestos'!D54))*12 -> 0.419895 | F7: =B7 -> 0.63 | G7: =B7*(1-'⚙️ Supuestos'!D55)/('⚙️ Supuestos'!D53-'⚙️ Supuestos'!D54) -> 0.01750875 | H7: Pierde TODO · recupera ticket S/5,000
A8: Rossy | B8: ='⚙️ Supuestos'!G10 -> 0.17 | C8: =B8*'⚙️ Supuestos'!D55 -> 0.05661 | D8: =C8+(B8*(1-'⚙️ Supuestos'!D55)/('⚙️ Supuestos'!D53-'⚙️ Supuestos'!D54))*5 -> 0.080232917 | E8: =C8+(B8*(1-'⚙️ Supuestos'!D55)/('⚙️ Supuestos'!D53-'⚙️ Supuestos'!D54))*12 -> 0.113305 | F8: =B8 -> 0.17 | G8: =B8*(1-'⚙️ Supuestos'!D55)/('⚙️ Supuestos'!D53-'⚙️ Supuestos'!D54) -> 0.0047245833 | H8: Pierde TODO · recupera ticket S/5,000
A9: Vera | B9: ='⚙️ Supuestos'!G11 -> 0.11 | C9: =B9*'⚙️ Supuestos'!D55 -> 0.03663 | D9: =C9+(B9*(1-'⚙️ Supuestos'!D55)/('⚙️ Supuestos'!D53-'⚙️ Supuestos'!D54))*5 -> 0.051915417 | E9: =C9+(B9*(1-'⚙️ Supuestos'!D55)/('⚙️ Supuestos'!D53-'⚙️ Supuestos'!D54))*12 -> 0.073315 | F9: =B9 -> 0.11 | G9: =B9*(1-'⚙️ Supuestos'!D55)/('⚙️ Supuestos'!D53-'⚙️ Supuestos'!D54) -> 0.0030570833 | H9: Pierde TODO · recupera ticket S/5,000
A10: Carlos | B10: ='⚙️ Supuestos'!G12 -> 0.06 | C10: =B10*'⚙️ Supuestos'!D55 -> 0.01998 | D10: =C10+(B10*(1-'⚙️ Supuestos'!D55)/('⚙️ Supuestos'!D53-'⚙️ Supuestos'!D54))*5 -> 0.0283175 | E10: =C10+(B10*(1-'⚙️ Supuestos'!D55)/('⚙️ Supuestos'!D53-'⚙️ Supuestos'!D54))*12 -> 0.03999 | F10: =B10 -> 0.06 | G10: =B10*(1-'⚙️ Supuestos'!D55)/('⚙️ Supuestos'!D53-'⚙️ Supuestos'!D54) -> 0.0016675 | H10: Pierde TODO · recupera ticket S/5,000
A11: Nicole | B11: ='⚙️ Supuestos'!G13 -> 0.03 | C11: =B11*'⚙️ Supuestos'!D55 -> 0.00999 | D11: =C11+(B11*(1-'⚙️ Supuestos'!D55)/('⚙️ Supuestos'!D53-'⚙️ Supuestos'!D54))*5 -> 0.01415875 | E11: =C11+(B11*(1-'⚙️ Supuestos'!D55)/('⚙️ Supuestos'!D53-'⚙️ Supuestos'!D54))*12 -> 0.019995 | F11: =B11 -> 0.03 | G11: =B11*(1-'⚙️ Supuestos'!D55)/('⚙️ Supuestos'!D53-'⚙️ Supuestos'!D54) -> 0.00083375 | H11: Pierde TODO · recupera ticket S/5,000
A13: ESCENARIOS DE SALIDA
A14: Escenario | C14: ¿Qué pasa con las acciones? | G14: Precio de salida
A15: Antes del cliff (abr 2026 – mar 2027) | C15: Pierde TODAS las acciones — 0% | G15: Solo recupera ticket S/5,000
A16: Durante el vesting (may 2027 – mar 2029) | C16: Conserva acciones ya ganadas · pierde las pendientes | G16: Precio según tipo de salida ↓
A17: Después del vesting completo (abr 2029+) | C17: Conserva el 100% — es socio permanente | G17: Precio de valoración del mercado
A18: GOOD LEAVER (acuerdo mutuo, enfermedad) | C18: Conserva acciones ganadas | G18: Precio de valoración actual (justo)
A19: BAD LEAVER (abandono, incumplimiento) | C19: Conserva acciones ganadas | G19: S/1 por acción (pierde valor real)
A20: Venta a tercero externo | C20: Debe ofrecer primero a los co-fundadores (30 días) | G20: Precio igual a la oferta externa

Sheet 7️⃣ Facturación
A1: TABLA 7 — Facturación por marca 2026-2032 (S/mes)
A2: Los inputs de Trazo están en ⚙️ Supuestos. Las líneas de Almaria y HugoTech son editables aquí. NETO 65%: lo que queda tras costos operativos (35% cubre planilla Trazo, tools, ads, logística). COLCHÓN = Neto - Sueldos equipo. DISTRIBUIBLE = Colchón - Reserva S/3,000 → se reparte como equity.
A6: Marca / Línea | B6: 2026 | C6: 2027 | D6: 2028 | E6: 2029 | F6: 2030 | G6: 2031 | H6: 2032 | I6: Total 2026-32 | J6: Nota
A7: 🔷 TRAZO — Agencia premium Lima
A8: Retainers + consultoría estratégica. Modelo premium: pocos clientes, tickets altos.
A9: Retainers + estrategia B2B | B9: ='⚙️ Supuestos'!B31 -> 9000 | C9: ='⚙️ Supuestos'!C31 -> 20000 | D9: ='⚙️ Supuestos'!D31 -> 28000 | E9: ='⚙️ Supuestos'!E31 -> 35000 | F9: ='⚙️ Supuestos'!F31 -> 42000 | G9: ='⚙️ Supuestos'!G31 -> 50000 | H9: ='⚙️ Supuestos'!H31 -> 58000 | I9: =SUM(B9:H9) -> 242000
A10: 🌿 ALMARIA — Ceremonias · Rituales · Kits
A11: Conservador 2027-2029 (equipo en formación). Escala con fe desde 2030 con 3-4 facilitadoras.
A12: B2C Kits delivery Lima | B12: 300 | C12: 1200 | D12: 3000 | E12: 6000 | F12: 15000 | G12: 22400 | H12: 30600
A13: B2B Ceremonias S/55/persona | B13: 500 | C13: 4400 | D13: 10000 | E13: 20000 | F13: 49500 | G13: 71500 | H13: 88000
A14: Rituales (bodas, quinceañeros) | B14: 400 | C14: 2900 | D14: 9000 | E14: 14000 | F14: 33600 | G14: 48000 | H14: 64800
A15: → SUBTOTAL ALMARIA | B15: =SUM(B12:B14) -> 1200 | C15: =SUM(C12:C14) -> 8500 | D15: =SUM(D12:D14) -> 22000 | E15: =SUM(E12:E14) -> 40000 | F15: =SUM(F12:F14) -> 98100 | G15: =SUM(G12:G14) -> 141900 | H15: =SUM(H12:H14) -> 183400 | I15: =SUM(B15:H15) -> 495100
A16: ⚡ HUGOTECH — Coaching · Talleres · Full Day · Programa
A17: 1:1 + Talleres B2B (S/1k-1.5k) + Full Day + Campamento + Programa propio (3 cohortes × 3 meses/año)
A18: 1:1 sesiones coaching | B18: 1600 | C18: 2400 | D18: 3000 | E18: 3600 | F18: 3200 | G18: 3200 | H18: 3200
A19: Talleres B2B S/1k-1.5k | B19: 2000 | C19: 6000 | D19: 10400 | E19: 14000 | F19: 18000 | G19: 21000 | H19: 24000
A20: Full Day (16→48 personas) | B20: 266 | C20: 833 | D20: 2400 | E20: 4500 | F20: 7200 | G20: 8400 | H20: 9600
A21: Campamento (4/año, 60p max) | B21: 416 | C21: 1000 | D21: 2000 | E21: 5000 | F21: 8333 | G21: 12500 | H21: 18000
A22: Programa propio 3m × 3/año | B22: 0 | C22: 1250 | D22: 5000 | E22: 12500 | F22: 18750 | G22: 25000 | H22: 33333
A23: → SUBTOTAL HUGOTECH | B23: =SUM(B18:B22) -> 4282 | C23: =SUM(C18:C22) -> 11483 | D23: =SUM(D18:D22) -> 22800 | E23: =SUM(E18:E22) -> 39600 | F23: =SUM(F18:F22) -> 55483 | G23: =SUM(G18:G22) -> 70100 | H23: =SUM(H18:H22) -> 88133 | I23: =SUM(B23:H23) -> 291881
A24: TOTAL QOCHIX | B24: =B9+B15+B23 -> 14482 | C24: =C9+C15+C23 -> 39983 | D24: =D9+D15+D23 -> 72800 | E24: =E9+E15+E23 -> 114600 | F24: =F9+F15+F23 -> 195583 | G24: =G9+G15+G23 -> 262000 | H24: =H9+H15+H23 -> 329533 | I24: =SUM(B24:H24) -> 1028981 | J24: =SUM(B24:H24) -> 1028981
A25: NETO 65% | B25: =B24*'⚙️ Supuestos'!D35 -> 9413.3 | C25: =C24*'⚙️ Supuestos'!D35 -> 25988.95 | D25: =D24*'⚙️ Supuestos'!D35 -> 47320 | E25: =E24*'⚙️ Supuestos'!D35 -> 74490 | F25: =F24*'⚙️ Supuestos'!D35 -> 127128.95 | G25: =G24*'⚙️ Supuestos'!D35 -> 170300 | H25: =H24*'⚙️ Supuestos'!D35 -> 214196.45 | J25: =SUM(B25:H25) -> 668837.65
A26: (-) SUELDOS EQUIPO | B26: ='⚙️ Supuestos'!B46 -> 7000 | C26: ='⚙️ Supuestos'!C46 -> 14000 | D26: ='⚙️ Supuestos'!D46 -> 22000 | E26: ='⚙️ Supuestos'!E46 -> 31000 | F26: ='⚙️ Supuestos'!F46 -> 43500 | G26: ='⚙️ Supuestos'!G46 -> 53500 | H26: ='⚙️ Supuestos'!H46 -> 66000 | J26: =SUM(B26:H26) -> 237000
A27: COLCHÓN OPERATIVO | B27: =B25-B26 -> 2413.3 | C27: =C25-C26 -> 11988.95 | D27: =D25-D26 -> 25320 | E27: =E25-E26 -> 43490 | F27: =F25-F26 -> 83628.95 | G27: =G25-G26 -> 116800 | H27: =H25-H26 -> 148196.45 | J27: =SUM(B27:H27) -> 431837.65
A28: DISTRIBUIBLE A SOCIOS | B28: =MAX(0,B27-'⚙️ Supuestos'!D50) -> 0 | C28: =MAX(0,C27-'⚙️ Supuestos'!D50) -> 8988.95 | D28: =MAX(0,D27-'⚙️ Supuestos'!D50) -> 22320 | E28: =MAX(0,E27-'⚙️ Supuestos'!D50) -> 40490 | F28: =MAX(0,F27-'⚙️ Supuestos'!D50) -> 80628.95 | G28: =MAX(0,G27-'⚙️ Supuestos'!D50) -> 113800 | H28: =MAX(0,H27-'⚙️ Supuestos'!D50) -> 145196.45 | J28: =SUM(B28:H28) -> 411424.35

Sheet 8️⃣ Sueldos
A1: TABLA 8 — Sueldos Qochix 2026-2032 (S/mes)
A2: Hugo/Rossy/Vera: el sueldo Qochix es ADICIONAL a su trabajo actual hasta el 'cruce'. Carlos/Nicole: es su sueldo principal desde 2026 (ya trabajan en Trazo). CRUCE = año en que el sueldo Qochix supera al corporativo → la decisión de salida se vuelve obvia.
A6: Persona | B6: Corp hoy S/mes | C6: 2026 | D6: 2027 | E6: 2028 | F6: 2029 | G6: 2030 | H6: 2031 | I6: 2032 | J6: Cruce | K6: Tope | L6: Contexto
A7: Hugo | B7: ='⚙️ Supuestos'!B9 -> 30000 | C7: ='⚙️ Supuestos'!B41 -> — | D7: ='⚙️ Supuestos'!C41 -> 2000 | E7: ='⚙️ Supuestos'!D41 -> 5000 | F7: ='⚙️ Supuestos'!E41 -> 9000 | G7: ='⚙️ Supuestos'!F41 -> 14000 | H7: ='⚙️ Supuestos'!G41 -> 20000 | I7: ='⚙️ Supuestos'!H41 -> 30000 | J7: 2032 | K7: S/30k | L7: ADICIONAL al corp hasta 2032 → decide dejar corporativo
A8: Rossy | B8: ='⚙️ Supuestos'!B10 -> 7000 | C8: ='⚙️ Supuestos'!B42 -> — | D8: ='⚙️ Supuestos'!C42 -> 1000 | E8: ='⚙️ Supuestos'!D42 -> 2500 | F8: ='⚙️ Supuestos'!E42 -> 4000 | G8: ='⚙️ Supuestos'!F42 -> 7500 | H8: ='⚙️ Supuestos'!G42 -> 9000 | I8: ='⚙️ Supuestos'!H42 -> 10000 | J8: 2030 | K8: S/10k | L8: ADICIONAL al corp hasta 2030 → cruce natural + libertad
A9: Vera | B9: ='⚙️ Supuestos'!B11 -> 6500 | C9: ='⚙️ Supuestos'!B43 -> — | D9: ='⚙️ Supuestos'!C43 -> 1000 | E9: ='⚙️ Supuestos'!D43 -> 2500 | F9: ='⚙️ Supuestos'!E43 -> 4000 | G9: ='⚙️ Supuestos'!F43 -> 7000 | H9: ='⚙️ Supuestos'!G43 -> 8500 | I9: ='⚙️ Supuestos'!H43 -> 10000 | J9: 2030 | K9: S/10k | L9: ADICIONAL al corp hasta 2030 → cruce natural + libertad
A10: Carlos | B10: ='⚙️ Supuestos'!B12 -> 5000 | C10: ='⚙️ Supuestos'!B44 -> 5000 | D10: ='⚙️ Supuestos'!C44 -> 6000 | E10: ='⚙️ Supuestos'!D44 -> 7000 | F10: ='⚙️ Supuestos'!E44 -> 8000 | G10: ='⚙️ Supuestos'!F44 -> 9000 | H10: ='⚙️ Supuestos'!G44 -> 10000 | I10: ='⚙️ Supuestos'!H44 -> 10000 | J10: 2026 ✓ | K10: S/10k | L10: Sueldo principal desde 2026 ✓
A11: Nicole | B11: ='⚙️ Supuestos'!B13 -> 2000 | C11: ='⚙️ Supuestos'!B45 -> 2000 | D11: ='⚙️ Supuestos'!C45 -> 4000 | E11: ='⚙️ Supuestos'!D45 -> 5000 | F11: ='⚙️ Supuestos'!E45 -> 6000 | G11: ='⚙️ Supuestos'!F45 -> 6000 | H11: ='⚙️ Supuestos'!G45 -> 6000 | I11: ='⚙️ Supuestos'!H45 -> 6000 | J11: 2026 ✓ | K11: S/6k | L11: Sueldo principal desde 2026 ✓
A12: TOTAL SUELDOS | C12: =SUM(C7:C11) -> 7000 | D12: =SUM(D7:D11) -> 14000 | E12: =SUM(E7:E11) -> 22000 | F12: =SUM(F7:F11) -> 31000 | G12: =SUM(G7:G11) -> 43500 | H12: =SUM(H7:H11) -> 53500 | I12: =SUM(I7:I11) -> 66000
A14: 💡 HITO HUGO 2032: ese año Qochix le paga S/30,000 = exactamente lo que gana en el corporativo hoy. Es la señal natural para considerar dejar su trabajo actual. Si cambias el sueldo en ⚙️ Supuestos el cruce cambia automáticamente.

Sheet 9️⃣ Equity Anual
A1: TABLA 9 — Retorno equity mensual por socio (S/mes) — APARTE del sueldo
A2: ¿Qué es esto? Lo que reciben por ser DUEÑOS del ecosistema — completamente aparte del sueldo. FÓRMULA: Distribuible del mes × % equity del socio El distribuible viene de 7️⃣ Facturación (colchón − reserva S/3,000). 2026: no hay distribución (colchón insuficiente). Desde 2027 empieza la distribución real. Todo en S/mes. Para el anual: multiplicar × 12.
A7: Persona | B7: % equity | C7: 2026 | D7: 2027 | E7: 2028 | F7: 2029 | G7: 2030 | H7: 2031 | I7: 2032 | J7: Acum 7a (anual) S/ | K7: Prom mensual S/
A8: Hugo | B8: ='⚙️ Supuestos'!G9 -> 0.63 | C8: =MAX(0,'7️⃣ Facturación'!B28*'⚙️ Supuestos'!G9) -> 0 | D8: =MAX(0,'7️⃣ Facturación'!C28*'⚙️ Supuestos'!G9) -> 5663.0385 | E8: =MAX(0,'7️⃣ Facturación'!D28*'⚙️ Supuestos'!G9) -> 14061.6 | F8: =MAX(0,'7️⃣ Facturación'!E28*'⚙️ Supuestos'!G9) -> 25508.7 | G8: =MAX(0,'7️⃣ Facturación'!F28*'⚙️ Supuestos'!G9) -> 50796.238 | H8: =MAX(0,'7️⃣ Facturación'!G28*'⚙️ Supuestos'!G9) -> 71694 | I8: =MAX(0,'7️⃣ Facturación'!H28*'⚙️ Supuestos'!G9) -> 91473.764 | J8: =SUM(C8:I8)*12 -> 3110368.1 | K8: =AVERAGE(D8:I8) -> 43199.557
A9: Rossy | B9: ='⚙️ Supuestos'!G10 -> 0.17 | C9: =MAX(0,'7️⃣ Facturación'!B28*'⚙️ Supuestos'!G10) -> 0 | D9: =MAX(0,'7️⃣ Facturación'!C28*'⚙️ Supuestos'!G10) -> 1528.1215 | E9: =MAX(0,'7️⃣ Facturación'!D28*'⚙️ Supuestos'!G10) -> 3794.4 | F9: =MAX(0,'7️⃣ Facturación'!E28*'⚙️ Supuestos'!G10) -> 6883.3 | G9: =MAX(0,'7️⃣ Facturación'!F28*'⚙️ Supuestos'!G10) -> 13706.922 | H9: =MAX(0,'7️⃣ Facturación'!G28*'⚙️ Supuestos'!G10) -> 19346 | I9: =MAX(0,'7️⃣ Facturación'!H28*'⚙️ Supuestos'!G10) -> 24683.396 | J9: =SUM(C9:I9)*12 -> 839305.67 | K9: =AVERAGE(D9:I9) -> 11657.023
A10: Vera | B10: ='⚙️ Supuestos'!G11 -> 0.11 | C10: =MAX(0,'7️⃣ Facturación'!B28*'⚙️ Supuestos'!G11) -> 0 | D10: =MAX(0,'7️⃣ Facturación'!C28*'⚙️ Supuestos'!G11) -> 988.7845 | E10: =MAX(0,'7️⃣ Facturación'!D28*'⚙️ Supuestos'!G11) -> 2455.2 | F10: =MAX(0,'7️⃣ Facturación'!E28*'⚙️ Supuestos'!G11) -> 4453.9 | G10: =MAX(0,'7️⃣ Facturación'!F28*'⚙️ Supuestos'!G11) -> 8869.1845 | H10: =MAX(0,'7️⃣ Facturación'!G28*'⚙️ Supuestos'!G11) -> 12518 | I10: =MAX(0,'7️⃣ Facturación'!H28*'⚙️ Supuestos'!G11) -> 15971.61 | J10: =SUM(C10:I10)*12 -> 543080.14 | K10: =AVERAGE(D10:I10) -> 7542.7797
A11: Carlos | B11: ='⚙️ Supuestos'!G12 -> 0.06 | C11: =MAX(0,'7️⃣ Facturación'!B28*'⚙️ Supuestos'!G12) -> 0 | D11: =MAX(0,'7️⃣ Facturación'!C28*'⚙️ Supuestos'!G12) -> 539.337 | E11: =MAX(0,'7️⃣ Facturación'!D28*'⚙️ Supuestos'!G12) -> 1339.2 | F11: =MAX(0,'7️⃣ Facturación'!E28*'⚙️ Supuestos'!G12) -> 2429.4 | G11: =MAX(0,'7️⃣ Facturación'!F28*'⚙️ Supuestos'!G12) -> 4837.737 | H11: =MAX(0,'7️⃣ Facturación'!G28*'⚙️ Supuestos'!G12) -> 6828 | I11: =MAX(0,'7️⃣ Facturación'!H28*'⚙️ Supuestos'!G12) -> 8711.787 | J11: =SUM(C11:I11)*12 -> 296225.53 | K11: =AVERAGE(D11:I11) -> 4114.2435
A12: Nicole | B12: ='⚙️ Supuestos'!G13 -> 0.03 | C12: =MAX(0,'7️⃣ Facturación'!B28*'⚙️ Supuestos'!G13) -> 0 | D12: =MAX(0,'7️⃣ Facturación'!C28*'⚙️ Supuestos'!G13) -> 269.6685 | E12: =MAX(0,'7️⃣ Facturación'!D28*'⚙️ Supuestos'!G13) -> 669.6 | F12: =MAX(0,'7️⃣ Facturación'!E28*'⚙️ Supuestos'!G13) -> 1214.7 | G12: =MAX(0,'7️⃣ Facturación'!F28*'⚙️ Supuestos'!G13) -> 2418.8685 | H12: =MAX(0,'7️⃣ Facturación'!G28*'⚙️ Supuestos'!G13) -> 3414 | I12: =MAX(0,'7️⃣ Facturación'!H28*'⚙️ Supuestos'!G13) -> 4355.8935 | J12: =SUM(C12:I12)*12 -> 148112.77 | K12: =AVERAGE(D12:I12) -> 2057.1217
A13: DISTRIBUIBLE TOTAL | C13: ='7️⃣ Facturación'!B28 -> 0 | D13: ='7️⃣ Facturación'!C28 -> 8988.95 | E13: ='7️⃣ Facturación'!D28 -> 22320 | F13: ='7️⃣ Facturación'!E28 -> 40490 | G13: ='7️⃣ Facturación'!F28 -> 80628.95 | H13: ='7️⃣ Facturación'!G28 -> 113800 | I13: ='7️⃣ Facturación'!H28 -> 145196.45
A15: Ejemplo Hugo 2032: S/91,473/mes equity × 12 = S/1,097,676/año. Aparte de su sueldo S/30,000/mes. El equity crece con el ecosistema — depende de que las marcas generen distribuible.

Sheet 🔟 Total Mensual
A1: TABLA 10 — Sueldo + Equity = ingreso total mensual (S/mes)
A2: Suma los dos flujos de Qochix para cada socio: 1) SUELDO QOCHIX: pago por el trabajo (editable en ⚙️ Supuestos) 2) RETORNO EQUITY: pago por ser dueño (calculado en 9️⃣ Equity Anual) Todo en S/mes. Para el anual: multiplicar × 12.
A6: Persona | B6: % equity | C6: 2026 | D6: 2027 | E6: 2028 | F6: 2029 | G6: 2030 | H6: 2031 | I6: 2032 | J6: Acum 7a S/ | K6: Total 2032 S/mes
A7: Hugo | B7: ='⚙️ Supuestos'!G9 -> 0.63 | C7: =IFERROR(VALUE('⚙️ Supuestos'!B41),0)+'9️⃣ Equity Anual'!C8 -> 0 | D7: =IFERROR(VALUE('⚙️ Supuestos'!C41),0)+'9️⃣ Equity Anual'!D8 -> 7663.0385 | E7: =IFERROR(VALUE('⚙️ Supuestos'!D41),0)+'9️⃣ Equity Anual'!E8 -> 19061.6 | F7: =IFERROR(VALUE('⚙️ Supuestos'!E41),0)+'9️⃣ Equity Anual'!F8 -> 34508.7 | G7: =IFERROR(VALUE('⚙️ Supuestos'!F41),0)+'9️⃣ Equity Anual'!G8 -> 64796.238 | H7: =IFERROR(VALUE('⚙️ Supuestos'!G41),0)+'9️⃣ Equity Anual'!H8 -> 91694 | I7: =IFERROR(VALUE('⚙️ Supuestos'!H41),0)+'9️⃣ Equity Anual'!I8 -> 121473.76 | J7: =SUM(C7:I7)*12 -> 4070368.1 | K7: =I7 -> 121473.76
A8: Rossy | B8: ='⚙️ Supuestos'!G10 -> 0.17 | C8: =IFERROR(VALUE('⚙️ Supuestos'!B42),0)+'9️⃣ Equity Anual'!C9 -> 0 | D8: =IFERROR(VALUE('⚙️ Supuestos'!C42),0)+'9️⃣ Equity Anual'!D9 -> 2528.1215 | E8: =IFERROR(VALUE('⚙️ Supuestos'!D42),0)+'9️⃣ Equity Anual'!E9 -> 6294.4 | F8: =IFERROR(VALUE('⚙️ Supuestos'!E42),0)+'9️⃣ Equity Anual'!F9 -> 10883.3 | G8: =IFERROR(VALUE('⚙️ Supuestos'!F42),0)+'9️⃣ Equity Anual'!G9 -> 21206.922 | H8: =IFERROR(VALUE('⚙️ Supuestos'!G42),0)+'9️⃣ Equity Anual'!H9 -> 28346 | I8: =IFERROR(VALUE('⚙️ Supuestos'!H42),0)+'9️⃣ Equity Anual'!I9 -> 34683.397 | J8: =SUM(C8:I8)*12 -> 1247305.7 | K8: =I8 -> 34683.397
A9: Vera | B9: ='⚙️ Supuestos'!G11 -> 0.11 | C9: =IFERROR(VALUE('⚙️ Supuestos'!B43),0)+'9️⃣ Equity Anual'!C10 -> 0 | D9: =IFERROR(VALUE('⚙️ Supuestos'!C43),0)+'9️⃣ Equity Anual'!D10 -> 1988.7845 | E9: =IFERROR(VALUE('⚙️ Supuestos'!D43),0)+'9️⃣ Equity Anual'!E10 -> 4955.2 | F9: =IFERROR(VALUE('⚙️ Supuestos'!E43),0)+'9️⃣ Equity Anual'!F10 -> 8453.9 | G9: =IFERROR(VALUE('⚙️ Supuestos'!F43),0)+'9️⃣ Equity Anual'!G10 -> 15869.184 | H9: =IFERROR(VALUE('⚙️ Supuestos'!G43),0)+'9️⃣ Equity Anual'!H10 -> 21018 | I9: =IFERROR(VALUE('⚙️ Supuestos'!H43),0)+'9️⃣ Equity Anual'!I10 -> 25971.609 | J9: =SUM(C9:I9)*12 -> 939080.14 | K9: =I9 -> 25971.609
A10: Carlos | B10: ='⚙️ Supuestos'!G12 -> 0.06 | C10: =IFERROR(VALUE('⚙️ Supuestos'!B44),0)+'9️⃣ Equity Anual'!C11 -> 5000 | D10: =IFERROR(VALUE('⚙️ Supuestos'!C44),0)+'9️⃣ Equity Anual'!D11 -> 6539.337 | E10: =IFERROR(VALUE('⚙️ Supuestos'!D44),0)+'9️⃣ Equity Anual'!E11 -> 8339.2 | F10: =IFERROR(VALUE('⚙️ Supuestos'!E44),0)+'9️⃣ Equity Anual'!F11 -> 10429.4 | G10: =IFERROR(VALUE('⚙️ Supuestos'!F44),0)+'9️⃣ Equity Anual'!G11 -> 13837.737 | H10: =IFERROR(VALUE('⚙️ Supuestos'!G44),0)+'9️⃣ Equity Anual'!H11 -> 16828 | I10: =IFERROR(VALUE('⚙️ Supuestos'!H44),0)+'9️⃣ Equity Anual'!I11 -> 18711.787 | J10: =SUM(C10:I10)*12 -> 956225.53 | K10: =I10 -> 18711.787
A11: Nicole | B11: ='⚙️ Supuestos'!G13 -> 0.03 | C11: =IFERROR(VALUE('⚙️ Supuestos'!B45),0)+'9️⃣ Equity Anual'!C12 -> 2000 | D11: =IFERROR(VALUE('⚙️ Supuestos'!C45),0)+'9️⃣ Equity Anual'!D12 -> 4269.6685 | E11: =IFERROR(VALUE('⚙️ Supuestos'!D45),0)+'9️⃣ Equity Anual'!E12 -> 5669.6 | F11: =IFERROR(VALUE('⚙️ Supuestos'!E45),0)+'9️⃣ Equity Anual'!F12 -> 7214.7 | G11: =IFERROR(VALUE('⚙️ Supuestos'!F45),0)+'9️⃣ Equity Anual'!G12 -> 8418.8685 | H11: =IFERROR(VALUE('⚙️ Supuestos'!G45),0)+'9️⃣ Equity Anual'!H12 -> 9414 | I11: =IFERROR(VALUE('⚙️ Supuestos'!H45),0)+'9️⃣ Equity Anual'!I12 -> 10355.894 | J11: =SUM(C11:I11)*12 -> 568112.77 | K11: =I11 -> 10355.894

Sheet 📊 ROI
A1: TABLA 11 — ROI: inversión total vs retorno acumulado 7 años
A2: ROI = Retorno total 7 años ÷ Inversión total. Inversión = ticket + capital cash + sweat equity 3 años. Retorno 7a = suma de (sueldo Qochix + equity mensual) × 12, para cada año 2026-2032. ×total 2032 = cuántas veces multiplica su sueldo actual con sueldo+equity en 2032.
A6: Persona | B6: % equity | C6: Total invertido S/ | D6: Retorno 7 años S/ | E6: ROI | F6: ×total vs hoy | G6: ROI anual promedio | H6: Punto eq. aprox. | I6: Nota
A7: Hugo | B7: ='⚙️ Supuestos'!G9 -> 0.63 | C7: ='4️⃣ Equity'!F7 -> 710179.36 | D7: ='🔟 Total Mensual'!J7 -> 4070368.1 | E7: =D7/C7 -> 5.7314649 | F7: ='🔟 Total Mensual'!I7/'⚙️ Supuestos'!B9 -> 4.0491255 | G7: =(D7/C7)^(1/7)-1 -> 0.28328661 | H7: =IF(C7=0,"-",IF(D7*3/7>=C7,"2029","2030+")) -> 2029 | I7: Inversión grande pero retorno enorme. Patrimonio adicional S/1.9M-3.8M en 2032
A8: Rossy | B8: ='⚙️ Supuestos'!G10 -> 0.17 | C8: ='4️⃣ Equity'!F8 -> 180151.82 | D8: ='🔟 Total Mensual'!J8 -> 1247305.7 | E8: =D8/C8 -> 6.9236363 | F8: ='🔟 Total Mensual'!I8/'⚙️ Supuestos'!B10 -> 4.9547709 | G8: =(D8/C8)^(1/7)-1 -> 0.31840169 | H8: =IF(C8=0,"-",IF(D8*3/7>=C8,"2029","2030+")) -> 2029 | I8: Muy buen ROI. Capital + tiempo reconocidos. Almaria es suya
A9: Vera | B9: ='⚙️ Supuestos'!G11 -> 0.11 | C9: ='4️⃣ Equity'!F9 -> 153069.55 | D9: ='🔟 Total Mensual'!J9 -> 939080.14 | E9: =D9/C9 -> 6.1349901 | F9: ='🔟 Total Mensual'!I9/'⚙️ Supuestos'!B11 -> 3.9956322 | G9: =(D9/C9)^(1/7)-1 -> 0.29582047 | H9: =IF(C9=0,"-",IF(D9*3/7>=C9,"2029","2030+")) -> 2029 | I9: Buen ROI. Sweat equity alto reconocido en el % propuesto
A10: Carlos | B10: ='⚙️ Supuestos'!G12 -> 0.06 | C10: ='4️⃣ Equity'!F10 -> 84159.091 | D10: ='🔟 Total Mensual'!J10 -> 956225.53 | E10: =D10/C10 -> 11.362118 | F10: ='🔟 Total Mensual'!I10/'⚙️ Supuestos'!B12 -> 3.7423574 | G10: =(D10/C10)^(1/7)-1 -> 0.41507644 | H10: =IF(C10=0,"-",IF(D10*3/7>=C10,"2029","2030+")) -> 2029 | I10: ROI alto porque ya cobra Trazo — inversión Qochix pequeña. 6% reconoce rol CEO
A11: Nicole | B11: ='⚙️ Supuestos'!G13 -> 0.03 | C11: ='4️⃣ Equity'!F11 -> 36663.636 | D11: ='🔟 Total Mensual'!J11 -> 568112.77 | E11: =D11/C11 -> 15.495265 | F11: ='🔟 Total Mensual'!I11/'⚙️ Supuestos'!B13 -> 5.1779468 | G11: =(D11/C11)^(1/7)-1 -> 0.47920522 | H11: =IF(C11=0,"-",IF(D11*3/7>=C11,"2029","2030+")) -> 2029 | I11: ROI alto porque ya cobra Trazo — inversión Qochix pequeña. 3% reconoce rol PM
A13: ⚠️ El ROI de Carlos y Nicole es alto porque su inversión en Qochix es pequeña (ya cobran de Trazo). No es un error — tienen una posición privilegiada: cobran desde el día 1 Y participan del equity.

Sheet 🎯 Apuesta Final
A1: 🎯 TABLA 12 — La apuesta final: HOY vs QOCHIX 2032 (todo S/mes)
A2: La tabla más importante. Todo en S/mes. SUELDO 32: sueldo Qochix en 2032 · EQUITY 32: retorno por ser dueño (aparte del sueldo) TOTAL 32 = Sueldo + Equity · ×equity = cuántas veces el equity solo multiplica su sueldo hoy ×total = cuántas veces el sueldo+equity juntos multiplican su sueldo hoy
A6: Persona | B6: Gana HOY S/mes | C6: 2027 S/mes | D6: 2029 S/mes | E6: Sueldo 2032 S/ | F6: Equity 2032 S/ | G6: TOTAL 2032 S/ | H6: ×equity vs hoy | I6: ×total vs hoy | J6: Ganancia S/mes 2032 | K6: Veredicto
A7: Hugo | B7: ='⚙️ Supuestos'!B9 -> 30000 | C7: ='🔟 Total Mensual'!D7 -> 7663.0385 | D7: ='🔟 Total Mensual'!F7 -> 34508.7 | E7: ='⚙️ Supuestos'!H41 -> 30000 | F7: ='9️⃣ Equity Anual'!I8 -> 91473.764 | G7: =E7+F7 -> 121473.76 | H7: =F7/B7 -> 3.0491255 | I7: =G7/B7 -> 4.0491255 | J7: =G7-B7 -> 91473.764 | K7: Multiplica ×4.0 su sueldo actual. Más patrimonio S/1.9M-3.8M
A8: Rossy | B8: ='⚙️ Supuestos'!B10 -> 7000 | C8: ='🔟 Total Mensual'!D8 -> 2528.1215 | D8: ='🔟 Total Mensual'!F8 -> 10883.3 | E8: ='⚙️ Supuestos'!H42 -> 10000 | F8: ='9️⃣ Equity Anual'!I9 -> 24683.396 | G8: =E8+F8 -> 34683.397 | H8: =F8/B8 -> 3.5261995 | I8: =G8/B8 -> 4.9547709 | J8: =G8-B8 -> 27683.396 | K8: Multiplica ×5.0 su sueldo actual. Almaria es suya
A9: Vera | B9: ='⚙️ Supuestos'!B11 -> 6500 | C9: ='🔟 Total Mensual'!D9 -> 1988.7845 | D9: ='🔟 Total Mensual'!F9 -> 8453.9 | E9: ='⚙️ Supuestos'!H43 -> 10000 | F9: ='9️⃣ Equity Anual'!I10 -> 15971.61 | G9: =E9+F9 -> 25971.609 | H9: =F9/B9 -> 2.4571707 | I9: =G9/B9 -> 3.9956322 | J9: =G9-B9 -> 19471.609 | K9: Multiplica ×4.0 su sueldo actual. Alianzas reconocidas
A10: Carlos | B10: ='⚙️ Supuestos'!B12 -> 5000 | C10: ='🔟 Total Mensual'!D10 -> 6539.337 | D10: ='🔟 Total Mensual'!F10 -> 10429.4 | E10: ='⚙️ Supuestos'!H44 -> 10000 | F10: ='9️⃣ Equity Anual'!I11 -> 8711.787 | G10: =E10+F10 -> 18711.787 | H10: =F10/B10 -> 1.7423574 | I10: =G10/B10 -> 3.7423574 | J10: =G10-B10 -> 13711.787 | K10: Multiplica ×3.7 su sueldo actual. Trazo crece, él crece
A11: Nicole | B11: ='⚙️ Supuestos'!B13 -> 2000 | C11: ='🔟 Total Mensual'!D11 -> 4269.6685 | D11: ='🔟 Total Mensual'!F11 -> 7214.7 | E11: ='⚙️ Supuestos'!H45 -> 6000 | F11: ='9️⃣ Equity Anual'!I12 -> 4355.8935 | G11: =E11+F11 -> 10355.894 | H11: =F11/B11 -> 2.1779467 | I11: =G11/B11 -> 5.1779468 | J11: =G11-B11 -> 8355.8935 | K11: Multiplica ×5.2 su sueldo actual. De S/2k a S/10k en 6 años
A13: 🎯 LA PREGUNTA DEL 2 DE ABRIL
A14: ¿Estás dispuesto a invertir tu tiempo y dinero hoy para multiplicar tu ingreso mensual entre ×3.7 y ×5.2 en 6 años — más el valor patrimonial de ser dueño de Qochix?
A16: ✅ SÍ → firma el pacto de socios antes del 15 de abril
A17: ⚠️ HAY DUDAS → hay que hablarlas el 2 de abril, no después
A19: VALOR PATRIMONIAL DE HUGO (63% de Qochix) — adicional al sueldo y equity mensual
A20: Si Qochix se valorara o vendiera, esto es lo que vale el 63% de Hugo. Independiente de los ingresos mensuales. Edita la valoración (azul) para ver distintos escenarios.
A21: Escenario | E21: Valoración Qochix S/ | F21: % Hugo | G21: Valor patrimonio Hugo S/
A22: Escenario conservador | E22: 3000000 | F22: ='⚙️ Supuestos'!G9 -> 0.63 | G22: =E22*F22 -> 1890000
A23: Escenario base | E23: 5000000 | F23: ='⚙️ Supuestos'!G9 -> 0.63 | G23: =E23*F23 -> 3150000
A24: Escenario optimista | E24: 7000000 | F24: ='⚙️ Supuestos'!G9 -> 0.63 | G24: =E24*F24 -> 4410000
